Workbook

Sheet Raw_Sales_Data
A1: Order_ID | B1: Order_Date | C1: Region | D1: City | E1: Category | F1: Product | G1: Units_Sold | H1: Unit_Price_INR | I1: Unit_Cost_INR | J1: Sales_Channel | K1: Salesperson | L1: Sales_INR | M1: Cost_INR | N1: Profit_INR
A2: ORD-0001 | B2: 45729 | C2: South | D2: Hyderabad | E2: Stationery | F2: Notebook Pack | G2: 2 | H2: 280 | I2: 140 | J2: Online | K2: Sara | L2: =G2*H2 -> 560 | M2: =G2*I2 -> 280 | N2: =L2-M2 -> 280
A3: ORD-0002 | B3: 45777 | C3: South | D3: Kochi | E3: Accessories | F3: Wireless Mouse | G3: 1 | H3: 650 | I3: 360 | J3: Online | K3: Ishaan | L3: =G3*H3 -> 650 | M3: =G3*I3 -> 360 | N3: =L3-M3 -> 290
A4: ORD-0003 | B4: 45661 | C4: West | D4: Surat | E4: Accessories | F4: Laptop Stand | G4: 2 | H4: 950 | I4: 520 | J4: Retail Store | K4: Sara | L4: =G4*H4 -> 1900 | M4: =G4*I4 -> 1040 | N4: =L4-M4 -> 860
A5: ORD-0004 | B5: 45710 | C5: East | D5: Patna | E5: Electronics | F5: 27-inch Monitor | G5: 1 | H5: 14500 | I5: 11200 | J5: Online | K5: Meera | L5: =G5*H5 -> 14500 | M5: =G5*I5 -> 11200 | N5: =L5-M5 -> 3300
A6: ORD-0005 | B6: 45680 | C6: South | D6: Chennai | E6: Accessories | F6: Laptop Backpack | G6: 2 | H6: 1600 | I6: 920 | J6: Corporate Sales | K6: Ishaan | L6: =G6*H6 -> 3200 | M6: =G6*I6 -> 1840 | N6: =L6-M6 -> 1360
A7: ORD-0006 | B7: 45843 | C7: South | D7: Kochi | E7: Accessories | F7: Mechanical Keyboard | G7: 3 | H7: 1980 | I7: 1350 | J7: Retail Store | K7: Sara | L7: =G7*H7 -> 5940 | M7: =G7*I7 -> 4050 | N7: =L7-M7 -> 1890
A8: ORD-0007 | B8: 45698 | C8: South | D8: Hyderabad | E8: Furniture | F8: Desk Lamp | G8: 1 | H8: 1200 | I8: 650 | J8: Retail Store | K8: Aarav | L8: =G8*H8 -> 1200 | M8: =G8*I8 -> 650 | N8: =L8-M8 -> 550
A9: ORD-0008 | B9: 45741 | C9: East | D9: Patna | E9: Storage | F9: External SSD 1TB | G9: 3 | H9: 7200 | I9: 5450 | J9: Marketplace | K9: Kabir | L9: =G9*H9 -> 21600 | M9: =G9*I9 -> 16350 | N9: =L9-M9 -> 5250
A10: ORD-0009 | B10: 45969 | C10: West | D10: Ahmedabad | E10: Stationery | F10: Notebook Pack | G10: 8 | H10: 280 | I10: 140 | J10: Retail Store | K10: Ishaan | L10: =G10*H10 -> 2240 | M10: =G10*I10 -> 1120 | N10: =L10-M10 -> 1120
A11: ORD-0010 | B11: 45770 | C11: West | D11: Pune | E11: Storage | F11: External SSD 1TB | G11: 2 | H11: 6480 | I11: 5450 | J11: Marketplace | K11: Aarav | L11: =G11*H11 -> 12960 | M11: =G11*I11 -> 10900 | N11: =L11-M11 -> 2060
A12: ORD-0011 | B12: 45691 | C12: West | D12: Mumbai | E12: Stationery | F12: Whiteboard | G12: 2 | H12: 1900 | I12: 1150 | J12: Retail Store | K12: Ishaan | L12: =G12*H12 -> 3800 | M12: =G12*I12 -> 2300 | N12: =L12-M12 -> 1500
A13: ORD-0012 | B13: 45731 | C13: North | D13: Jaipur | E13: Furniture | F13: Desk Lamp | G13: 3 | H13: 1140 | I13: 650 | J13: Marketplace | K13: Diya | L13: =G13*H13 -> 3420 | M13: =G13*I13 -> 1950 | N13: =L13-M13 -> 1470
... A17: ORD-0016 | B17: 45986 | C17: South | D17: Hyderabad | E17: Furniture | F17: Desk Lamp | G17: 6 | H17: 1200 | I17: 650 | J17: Marketplace | K17: Aarav | L17: =G17*H17 -> 7200 | M17: =G17*I17 -> 3900 | N17: =L17-M17 -> 3300
A18: ORD-0017 | B18: 45914 | C18: North | E18: Accessories | F18: USB-C Hub | G18: 2 | H18: 1800 | I18: 1050 | J18: Retail Store | K18: Ishaan | L18: =G18*H18 -> 3600 | M18: =G18*I18 -> 2100 | N18: =L18-M18 -> 1500
A19: ORD-0018 | B19: 45759 | C19: South | D19: Chennai | E19: Accessories | F19: Laptop Backpack | G19: 3 | H19: 1440 | I19: 920 | J19: Retail Store | K19: Kabir | L19: =G19*H19 -> 4320 | M19: =G19*I19 -> 2760 | N19: =L19-M19 -> 1560
A20: ORD-0019 | B20: 45715 | C20: West | D20: Mumbai | E20: Furniture | F20: Office Chair | G20: 2 | H20: 8500 | I20: 6100 | J20: Marketplace | K20: Kabir | L20: =G20*H20 -> 17000 | M20: =G20*I20 -> 12200 | N20: =L20-M20 -> 4800
A21: ORD-0020 | B21: 45701 | C21: West | D21: Mumbai | E21: Accessories | F21: Laptop Stand | G21: 6 | H21: 950 | I21: 520 | J21: Corporate Sales | K21: Aarav | L21: =G21*H21 -> 5700 | M21: =G21*I21 -> 3120 | N21: =L21-M21 -> 2580
A22: ORD-0021 | B22: 45742 | C22: West | D22: Pune | E22: Furniture | F22: Desk Lamp | G22: 3 | H22: 1080 | I22: 650 | J22: Marketplace | K22: Ishaan | L22: =G22*H22 -> 3240 | M22: =G22*I22 -> 1950 | N22: =L22-M22 -> 1290
A23: ORD-0022 | B23: 45817 | C23: East | D23: Bhubaneswar | E23: Storage | F23: Portable HDD 2TB | G23: 4 | H23: 5600 | I23: 4100 | J23: Corporate Sales | K23: Sara | L23: =G23*H23 -> 22400 | M23: =G23*I23 -> 16400 | N23: =L23-M23 -> 6000
A24: ORD-0023 | B24: 45773 | C24: North | D24: Chandigarh | E24: Storage | F24: Portable HDD 2TB | G24: 2 | H24: 5600 | I24: 4100 | J24: Online | K24: Kabir | L24: =G24*H24 -> 11200 | M24: =G24*I24 -> 8200 | N24: =L24-M24 -> 3000
A25: ORD-0024 | B25: 46020 | C25: South | D25: Bengaluru | E25: Furniture | F25: Office Chair | G25: 1 | H25: 8500 | I25: 6100 | J25: Online | K25: Diya | L25: =G25*H25 -> 8500 | M25: =G25*I25 -> 6100 | N25: =L25-M25 -> 2400
A26: ORD-0025 | B26: 45779 | C26: South | D26: Hyderabad | E26: Accessories | F26: Laptop Backpack | G26: 2 | H26: 1440 | I26: 920 | J26: Marketplace | K26: Sara | L26: =G26*H26 -> 2880 | M26: =G26*I26 -> 1840 | N26: =L26-M26 -> 1040
A27: ORD-0026 | B27: 45953 | C27: East | D27: Bhubaneswar | E27: Storage | F27: Portable HDD 2TB | G27: 1 | H27: 5040 | I27: 4100 | J27: Corporate Sales | K27: Diya | L27: =G27*H27 -> 5040 | M27: =G27*I27 -> 4100 | N27: =L27-M27 -> 940
A28: ORD-0027 | B28: 45839 | C28: East | D28: Ranchi | E28: Accessories | F28: Laptop Stand | G28: 1 | H28: 902.5 | I28: 520 | J28: Corporate Sales | K28: Meera | L28: =G28*H28 -> 902.5 | M28: =G28*I28 -> 520 | N28: =L28-M28 -> 382.5
A29: ORD-0028 | B29: 45689 | C29: East | D29: Kolkata | E29: Furniture | F29: Desk Lamp | G29: 4 | H29: 1200 | I29: 650 | J29: Corporate Sales | K29: Sara | L29: =G29*H29 -> 4800 | M29: =G29*I29 -> 2600 | N29: =L29-M29 -> 2200
A30: ORD-0029 | B30: 45887 | C30: North | D30: Delhi | E30: Accessories | F30: Laptop Stand | G30: 1 | H30: 855 | I30: 520 | J30: Retail Store | K30: Meera | L30: =G30*H30 -> 855 | M30: =G30*I30 -> 520 | N30: =L30-M30 -> 335
... A59: ORD-0058 | B59: 46004 | C59: West | D59: Pune | E59: Electronics | F59: Headphones | G59: 4 | H59: 2280 | I59: 1450 | J59: Retail Store | K59: Ishaan | L59: =G59*H59 -> 9120 | M59: =G59*I59 -> 5800 | N59: =L59-M59 -> 3320
A60: ORD-0059 | B60: 45804 | C60: North | E60: Storage | F60: Portable HDD 2TB | G60: 5 | H60: 5600 | I60: 4100 | J60: Retail Store | K60: Meera | L60: =G60*H60 -> 28000 | M60: =G60*I60 -> 20500 | N60: =L60-M60 -> 7500
A61: ORD-0060 | B61: 45919 | C61: North | D61: Chandigarh | E61: Storage | F61: External SSD 1TB | G61: 2 | H61: 7200 | I61: 5450 | J61: Corporate Sales | K61: Sara | L61: =G61*H61 -> 14400 | M61: =G61*I61 -> 10900 | N61: =L61-M61 -> 3500
A62: ORD-0061 | B62: 45829 | C62: West | D62: Mumbai | E62: Electronics | F62: 27-inch Monitor | G62: 3 | H62: 13050 | I62: 11200 | J62: Online | K62: Diya | L62: =G62*H62 -> 39150 | M62: =G62*I62 -> 33600 | N62: =L62-M62 -> 5550
A63: ORD-0062 | B63: 45681 | C63: North | D63: Jaipur | E63: Stationery | F63: Whiteboard | G63: 1 | H63: 1900 | I63: 1150 | J63: Retail Store | K63: Meera | L63: =G63*H63 -> 1900 | M63: =G63*I63 -> 1150 | N63: =L63-M63 -> 750
A64: ORD-0063 | B64: 45757 | C64: South | D64: Kochi | E64: Electronics | F64: Headphones | G64: 6 | H64: 2160 | I64: 1450 | J64: Corporate Sales | K64: Meera | L64: =G64*H64 -> 12960 | M64: =G64*I64 -> 8700 | N64: =L64-M64 -> 4260
A65: ORD-0064 | B65: 45712 | C65: East | D65: Bhubaneswar | E65: Accessories | F65: USB-C Hub | G65: 4 | H65: 1800 | I65: 1050 | J65: Corporate Sales | K65: Diya | L65: =G65*H65 -> 7200 | M65: =G65*I65 -> 4200 | N65: =L65-M65 -> 3000
A66: ORD-0065 | B66: 45891 | C66: West | D66: Surat | E66: Accessories | F66: Wireless Mouse | G66: 3 | H66: 650 | I66: 360 | J66: Retail Store | K66: Meera | L66: =G66*H66 -> 1950 | M66: =G66*I66 -> 1080 | N66: =L66-M66 -> 870
A67: ORD-0066 | B67: 45876 | C67: North | D67: Chandigarh | E67: Furniture | F67: Office Chair | G67: 5 | H67: 7650 | I67: 6100 | J67: Corporate Sales | K67: Diya | L67: =G67*H67 -> 38250 | M67: =G67*I67 -> 30500 | N67: =L67-M67 -> 7750
A68: ORD-0067 | B68: 45924 | C68: East | D68: Ranchi | E68: Electronics | F68: 27-inch Monitor | G68: 4 | H68: 14500 | I68: 11200 | J68: Corporate Sales | K68: Sara | L68: =G68*H68 -> 58000 | M68: =G68*I68 -> 44800 | N68: =L68-M68 -> 13200
A69: ORD-0068 | B69: 45778 | C69: West | D69: Ahmedabad | E69: Storage | F69: External SSD 1TB | G69: 1 | H69: 7200 | I69: 5450 | J69: Marketplace | K69: Kabir | L69: =G69*H69 -> 7200 | M69: =G69*I69 -> 5450 | N69: =L69-M69 -> 1750
A70: ORD-0069 | B70: 46013 | C70: North | D70: Delhi | E70: Accessories | F70: USB-C Hub | G70: 1 | H70: 1710 | I70: 1050 | J70: Retail Store | K70: Sara | L70: =G70*H70 -> 1710 | M70: =G70*I70 -> 1050 | N70: =L70-M70 -> 660
A71: ORD-0070 | B71: 45896 | C71: West | D71: Mumbai | E71: Electronics | F71: Headphones | G71: 2 | H71: 2160 | I71: 1450 | J71: Corporate Sales | K71: Aarav | L71: =G71*H71 -> 4320 | M71: =G71*I71 -> 2900 | N71: =L71-M71 -> 1420
...

Sheet Sales Summary
A1: Metric | B1: Value | D1: Region | E1: Total Sales | G1: Category | H1: Total Profit
A2: Total Sales | B2: =SUM(Raw_Sales_Data!L:L) -> 1750265.5 | D2: North | E2: =SUMIF(Raw_Sales_Data!C:C,D2,Raw_Sales_Data!L:L) -> 241601 | G2: Electronics | H2: =SUMIF(Raw_Sales_Data!E$2:E$182,G2,Raw_Sales_Data!N$2:N$182) -> 127840
A3: Total Cost | B3: =SUM(Raw_Sales_Data!M:M) -> 1254550 | D3: South | E3: =SUMIF(Raw_Sales_Data!C:C,D3,Raw_Sales_Data!L:L) -> 445000 | G3: Furniture | H3: =SUMIF(Raw_Sales_Data!E$2:E$182,G3,Raw_Sales_Data!N$2:N$182) -> 86560
A4: Total Profit | B4: =SUM(Raw_Sales_Data!N:N) -> 495715.5 | D4: East | E4: =SUMIF(Raw_Sales_Data!C:C,D4,Raw_Sales_Data!L:L) -> 460998.5 | G4: Stationery | H4: =SUMIF(Raw_Sales_Data!E$2:E$182,G4,Raw_Sales_Data!N$2:N$182) -> 22388
A5: Profit Margin | B5: =B4/B2 -> 0.28322303 | D5: West | E5: =SUMIF(Raw_Sales_Data!C:C,D5,Raw_Sales_Data!L:L) -> 602666 | G5: Accessories | H5: =SUMIF(Raw_Sales_Data!E$2:E$182,G5,Raw_Sales_Data!N$2:N$182) -> 116177.5
G6: Storage | H6: =SUMIF(Raw_Sales_Data!E$2:E$182,G6,Raw_Sales_Data!N$2:N$182) -> 142090
H11: =COUNTA(Raw_Sales_Data!E:E) -> 0
H12: =COUNTA(Raw_Sales_Data!A2:A182) -> 180
F13: =COUNTIF(Raw_Sales_Data!E:E,"Electronics") -> 0

Sheet Dashboard
A1: RETAIL SALES ANALYTICS DASHBOARD | B1: RETAIL SALES ANALYTICS DASHBOARD
A3: Total Sales | B3: ='Sales Summary'!B2 -> 1750265.5 | D3: Total Profit | E3: ='Sales Summary'!B4 -> 495715.5 | G3: Profit Margin | H3: ='Sales Summary'!B5 -> 0.28322303
A19: BUSINESS INSIGHTS
A21: West generated the highest regional sales.
A23: Storage generated the highest category profit.
A25: Overall profit margin was 28.32%.

Sheet Start_Here
A1: RETAIL SALES ANALYTICS — PROJECT GUIDE
A2: Purpose | B2: Practise Excel data cleaning, formulas, PivotTables, charts, and business insights.
A3: Important | B3: Work on a copy of Raw_Sales_Data before cleaning. Keep the raw data unchanged.
A4: Dataset | B4: 181 rows including one intentional duplicate; several small data-quality issues are included.
A5: Columns | B5: Order_ID, Order_Date, Region, City, Category, Product, Units_Sold, Unit_Price_INR, Unit_Cost_INR, Sales_Channel, Salesperson
A6: Project stages | B6: 1. Inspect and clean data; 2. Calculate Sales, Cost, Profit; 3. Answer business questions; 4. Build PivotTables/charts; 5. Create a dashboard.
A7: Stage 1 — Inspect | B7: Turn the raw range into an Excel Table (Ctrl+T). Check blanks, duplicates, inconsistent capitalization, and extra spaces.
A8: Stage 2 — Calculate | B8: Add columns: Sales_INR = Units_Sold × Unit_Price_INR; Cost_INR = Units_Sold × Unit_Cost_INR; Profit_INR = Sales_INR − Cost_INR.
A9: Stage 3 — Questions | B9: What is total sales? What is total profit? Which product has the highest sales? Which region has the highest profit? Which month has the highest sales?
A10: Stage 4 — Analysis | B10: Create PivotTables for sales by region, profit by category, monthly sales, and top products.
A11: Stage 5 — Dashboard | B11: Show Total Sales, Total Profit, Total Orders, and Profit Margin, plus 2–3 charts.
A12: Rules | B12: Do not delete rows until you have checked duplicates. Do not replace blanks blindly; decide whether each blank can be recovered or should be marked.
